<?xml version="1.0" encoding="utf-8"?>
<robot
  name="cengaver_rover">
  <link
    name="base_link">
    <inertial>
      <origin
        xyz="-7.52548912075213E-10 0.00133985465192443 0.215427058661404"
        rpy="0 0 0" />
      <mass
        value="40.1379079681851" />
      <inertia
        ixx="1.16900142531114"
        ixy="0.00108521345983988"
        ixz="0.133695257924101"
        iyy="1.25971045307986"
        iyz="-0.00509655633734715"
        izz="2.16268381145349" />
    </inertial>
    <visual>
      <origin
        xyz="0 0 0"
        rpy="0 0 0" />
      <geometry>
        <mesh
          filename="package://cengaver_rover/meshes/base_link.STL" />
      </geometry>
      <material
        name="">
        <color rgba="0.8 0.8 0.8 1"/> 
       <specular rgba="0.5 0.5 0.5 1"/>
      </material>
    </visual>
    <collision>
      <origin
        xyz="0 0 0"
        rpy="0 0 0" />
      <geometry>
        <mesh
          filename="package://cengaver_rover/meshes/base_link.STL" />
      </geometry>
    </collision>
  </link>

  <gazebo reference="base_link">
    <material>PR2/Grey1   </material>
  </gazebo>

  <link
    name="wheel1">
    <inertial>
      <origin
        xyz="0.000122612981227871 1.98732798040169E-06 -0.0576270454609041"
        rpy="0 0 0" />
      <mass
        value="1.37210716126655" />
      <inertia
        ixx="0.00789978615382761"
        ixy="6.69001163873593E-07"
        ixz="-1.06816776348498E-06"
        iyy="0.00786607684314157"
        iyz="-2.52943863764599E-08"
        izz="0.0127489505715837" />
    </inertial>
    <visual>
      <origin
        xyz="0 0 0"
        rpy="0 0 0" />
      <geometry>
        <mesh
          filename="package://cengaver_rover/meshes/wheel1.STL" />
      </geometry>
      <material
        name="">
        <color
          rgba="1 0 0 1" />
      </material>
    </visual>
    <collision>
      <origin
        xyz="0 0 0"
        rpy="0 0 0" />
      <geometry>
        <mesh
          filename="package://cengaver_rover/meshes/wheel1.STL" />
      </geometry>
    </collision>
  </link>
  
  <gazebo reference="wheel1">
    <material>Gazebo/Red</material>
  </gazebo>

  <joint
    name="Joint1"
    type="continuous">
    <origin
      xyz="0.27998 -0.33703 0.1172"
      rpy="-1.5708 -1.3503 1.5708" />
    <parent
      link="base_link" />
    <child
      link="wheel1" />
    <axis
      xyz="0 0 1" />
  </joint>
  <link
    name="wheel2">
    <inertial>
      <origin
        xyz="0.000122612982376979 -1.98732819572944E-06 0.0576270454601775"
        rpy="0 0 0" />
      <mass
        value="1.37210716127023" />
      <inertia
        ixx="0.00789978615355137"
        ixy="-6.69001094576813E-07"
        ixz="1.06816769245835E-06"
        iyy="0.00786607684342403"
        iyz="-2.52943345498765E-08"
        izz="0.0127489505715954" />
    </inertial>
    <visual>
      <origin
        xyz="0 0 0"
        rpy="0 0 0" />
      <geometry>
        <mesh
          filename="package://cengaver_rover/meshes/wheel2.STL" />
      </geometry>
      <material
        name="">
        <color
          rgba="0 0 0 1" />
      </material>
    </visual>
    <collision>
      <origin
        xyz="0 0 0"
        rpy="0 0 0" />
      <geometry>
        <mesh
          filename="package://cengaver_rover/meshes/wheel2.STL" />
      </geometry>
    </collision>
  </link>

  <gazebo reference="wheel2">
    <material>Gazebo/Black</material>
  </gazebo>

  <joint
    name="Joint2"
    type="continuous">
    <origin
      xyz="0.27998 0.3379 0.11736"
      rpy="-1.5708 0 -1.5708" />
    <parent
      link="base_link" />
    <child
      link="wheel2" />
    <axis
      xyz="0 0 -1" />
  </joint>
  <link
    name="wheel3">
    <inertial>
      <origin
        xyz="0.000122612982376591 1.98732819672864E-06 -0.0576270454601775"
        rpy="0 0 0" />
      <mass
        value="1.37210716127024" />
      <inertia
        ixx="0.00789978615355147"
        ixy="6.69001094577587E-07"
        ixz="-1.06816769246315E-06"
        iyy="0.00786607684342405"
        iyz="-2.52943345351912E-08"
        izz="0.0127489505715955" />
    </inertial>
    <visual>
      <origin
        xyz="0 0 0"
        rpy="0 0 0" />
      <geometry>
        <mesh
          filename="package://cengaver_rover/meshes/wheel3.STL" />
      </geometry>
      <material
        name="">
        <color
          rgba="1 0 0 1" />
      </material>
    </visual>
    <collision>
      <origin
        xyz="0 0 0"
        rpy="0 0 0" />
      <geometry>
        <mesh
          filename="package://cengaver_rover/meshes/wheel3.STL" />
      </geometry>
    </collision>
  </link>

  <gazebo reference="wheel3">
    <material>Gazebo/Red</material>
  </gazebo>

  <joint
    name="Joint3"
    type="continuous">
    <origin
      xyz="-0.27998 -0.33703 0.1172"
      rpy="1.5708 0 1.5708" />
    <parent
      link="base_link" />
    <child
      link="wheel3" />
    <axis
      xyz="0 0 1" />
  </joint>
  <link
    name="wheel4">
    <inertial>
      <origin
        xyz="0.000122612982376147 1.98732819589598E-06 -0.0576270454601775"
        rpy="0 0 0" />
      <mass
        value="1.37210716127023" />
      <inertia
        ixx="0.00789978615355138"
        ixy="6.69001094539057E-07"
        ixz="-1.06816769244459E-06"
        iyy="0.007866076843424"
        iyz="-2.52943345308376E-08"
        izz="0.0127489505715954" />
    </inertial>
    <visual>
      <origin
        xyz="0 0 0"
        rpy="0 0 0" />
      <geometry>
        <mesh
          filename="package://cengaver_rover/meshes/wheel4.STL" />
      </geometry>
      <material
        name="">
        <color
          rgba="1 0 0 1" />
      </material>
    </visual>
    <collision>
      <origin
        xyz="0 0 0"
        rpy="0 0 0" />
      <geometry>
        <mesh
          filename="package://cengaver_rover/meshes/wheel4.STL" />
      </geometry>
    </collision>
  </link>

  <gazebo reference="wheel4">
    <material>Gazebo/Red</material>
  </gazebo>

  <joint
    name="Joint4"
    type="continuous">
    <origin
      xyz="-0.279980377966613 0.337900459483096 0.11735723023063"
      rpy="1.5707963267949 0 1.5707963267949" />
    <parent
      link="base_link" />
    <child
      link="wheel4" />
    <axis
      xyz="0 0 1" />
  </joint>
</robot>