<?xml version="1.0" ?>
<!-- =================================================================================== -->
<!-- |    This document was autogenerated by xacro from cengaver.urdf.xacro            | -->
<!-- |    EDITING THIS FILE BY HAND IS NOT RECOMMENDED                                 | -->
<!-- =================================================================================== -->
<robot name="cengaver_rover">
  <!-- MATERIALS -->
  <material name="chassis_material">
    <color rgba="0.8 0.8 0.8 1"/>
    <specular rgba="0.5 0.5 0.5 1"/>
  </material>
  <material name="red_wheel_material">
    <color rgba="1 0 0 1"/>
  </material>
  <material name="black_wheel_material">
    <color rgba="0 0 0 1"/>
  </material>
  <!-- BASE LINK -->
  <link name="base_link">
    </link>
  <joint name="chassis_joint" type="fixed">
    <parent link="base_link"/>
    <child link="chassis"/>
    <origin xyz="0 0 0.18"/>
  </joint>
  <link name="chassis">
    <visual>
      <origin rpy="0 0 1.5707963267948966" xyz="0 0 -0.18"/>
      <geometry>
        <mesh filename="package://cengaver_rover_description/meshes/base_link.STL"/>
      </geometry>
      <material name="chassis_material"/>
    </visual>
    <collision>
      <origin rpy="0 0 1.5707963267948966" xyz="0 0 -0.18"/>
      <geometry>
        <mesh filename="package://cengaver_rover_description/meshes/base_link.STL"/>
      </geometry>
    </collision>
    <inertial>
      <origin rpy="0 0 0" xyz="-7.52548912075213E-10 0.00133985465192443 0.215427058661404"/>
      <mass value="40.1379079681851"/>
      <inertia ixx="1.16900142531114" ixy="0.00108521345983988" ixz="0.133695257924101" iyy="1.25971045307986" iyz="-0.00509655633734715" izz="2.16268381145349"/>
    </inertial>
  </link>
  <gazebo reference="chassis">
    <material>PR2/Grey1   </material>
  </gazebo>
  <!-- FRONT LEFT WHEEL LINK -->
  <joint name="front_left_wheel_joint" type="continuous">
    <parent link="base_link"/>
    <child link="front_left_wheel"/>
    <origin rpy=" 0 -1.5708 -1.5708" xyz="0.3379 0.39398 0.11736"/>
    <axis xyz="0 0 1"/>
  </joint>
  <link name="front_left_wheel">
    <visual>
      <origin rpy="0 0 0" xyz="0 0 0"/>
      <geometry>
        <mesh filename="package://cengaver_rover_description/meshes/wheel1.STL"/>
      </geometry>
      <material name="red_wheel_material"/>
    </visual>
    <collision>
      <origin rpy="0 0 0" xyz="0 0 0"/>
      <geometry>
        <mesh filename="package://cengaver_rover_description/meshes/wheel1.STL"/>
      </geometry>
    </collision>
    <inertial>
      <origin rpy="0 0 0" xyz="0.000122612981227871 1.98732798040169E-06 -0.0576270454609041"/>
      <mass value="1.37210716126655"/>
      <inertia ixx="0.00789978615382761" ixy="6.69001163873593E-07" ixz="-1.06816776348498E-06" iyy="0.00786607684314157" iyz="-2.52943863764599E-08" izz="0.0127489505715837"/>
    </inertial>
  </link>
  <gazebo reference="front_left_wheel">
    <material>Gazebo/Red</material>
  </gazebo>
  <!-- FRONT RIGHT WHEEL LINK -->
  <joint name="front_right_wheel_joint" type="continuous">
    <parent link="base_link"/>
    <child link="front_right_wheel"/>
    <origin rpy=" 0 1.5708 -1.5708" xyz="0.3379 -0.39398 0.11736"/>
    <axis xyz="0 0 -1"/>
  </joint>
  <link name="front_right_wheel">
    <visual>
      <origin rpy="0 0 0" xyz="0 0 0"/>
      <geometry>
        <mesh filename="package://cengaver_rover_description/meshes/wheel1.STL"/>
      </geometry>
      <material name="red_wheel_material"/>
    </visual>
    <collision>
      <origin rpy="0 0 0" xyz="0 0 0"/>
      <geometry>
        <mesh filename="package://cengaver_rover_description/meshes/wheel1.STL"/>
      </geometry>
    </collision>
    <inertial>
      <origin rpy="0 0 0" xyz="0.000122612982376591 1.98732819672864E-06 -0.0576270454601775"/>
      <mass value="1.37210716127024"/>
      <inertia ixx="0.00789978615355147" ixy="6.69001094577587E-07" ixz="-1.06816769246315E-06" iyy="0.00786607684342405" iyz="-2.52943345351912E-08" izz="0.0127489505715955"/>
    </inertial>
  </link>
  <gazebo reference="front_right_wheel">
    <material>Gazebo/Red</material>
  </gazebo>
  <!-- BACK LEFT WHEEL LINK -->
  <joint name="back_left_wheel_joint" type="continuous">
    <parent link="base_link"/>
    <child link="back_left_wheel"/>
    <origin rpy=" 0 -1.5708 -1.5708" xyz="-0.3379 0.39398 0.11736"/>
    <axis xyz="0 0 1"/>
  </joint>
  <link name="back_left_wheel">
    <visual>
      <origin rpy="0 0 0" xyz="0 0 0"/>
      <geometry>
        <mesh filename="package://cengaver_rover_description/meshes/wheel1.STL"/>
      </geometry>
      <material name="black_wheel_material"/>
    </visual>
    <collision>
      <origin rpy="0 0 0" xyz="0 0 0"/>
      <geometry>
        <mesh filename="package://cengaver_rover_description/meshes/wheel1.STL"/>
      </geometry>
    </collision>
    <inertial>
      <origin rpy="0 0 0" xyz="0.000122612982376979 1.98732819572944E-06 -0.0576270454601775"/>
      <mass value="1.37210716127023"/>
      <inertia ixx="0.00789978615355137" ixy="-6.69001094576813E-07" ixz="1.06816769245835E-06" iyy="0.00786607684342403" iyz="-2.52943345498765E-08" izz="0.0127489505715954"/>
    </inertial>
  </link>
  <gazebo reference="back_left_wheel">
    <material>Gazebo/Black</material>
  </gazebo>
  <!-- BACK RIGHT WHEEL LINK -->
  <joint name="back_right_wheel_joint" type="continuous">
    <parent link="base_link"/>
    <child link="back_right_wheel"/>
    <origin rpy=" 0 1.5708 -1.5708" xyz="-0.3379 -0.39398 0.11736"/>
    <axis xyz="0 0 -1"/>
  </joint>
  <link name="back_right_wheel">
    <visual>
      <origin rpy="0 0 0" xyz="0 0 0"/>
      <geometry>
        <mesh filename="package://cengaver_rover_description/meshes/wheel1.STL"/>
      </geometry>
      <material name="red_wheel_material"/>
    </visual>
    <collision>
      <origin rpy="0 0 0" xyz="0 0 0"/>
      <geometry>
        <mesh filename="package://cengaver_rover_description/meshes/wheel1.STL"/>
      </geometry>
    </collision>
    <inertial>
      <origin rpy="0 0 0" xyz="0.000122612982376147 1.98732819589598E-06 -0.0576270454601775"/>
      <mass value="1.37210716127023"/>
      <inertia ixx="0.00789978615355138" ixy="6.69001094539057E-07" ixz="-1.06816769244459E-06" iyy="0.007866076843424" iyz="-2.52943345308376E-08" izz="0.0127489505715954"/>
    </inertial>
  </link>
  <gazebo reference="back_right_wheel">
    <material>Gazebo/Red</material>
  </gazebo>
  <gazebo reference="front_left_wheel">
    <mu1 value="0.2"/>
    <mu2 value="0.2"/>
  </gazebo>
  <gazebo reference="front_right_wheel">
    <mu1 value="0.2"/>
    <mu2 value="0.2"/>
  </gazebo>
  <gazebo reference="back_left_wheel">
    <mu1 value="0.2"/>
    <mu2 value="0.2"/>
  </gazebo>
  <gazebo reference="back_right_wheel">
    <mu1 value="0.2"/>
    <mu2 value="0.2"/>
  </gazebo>
  <gazebo>
    <plugin filename="libgazebo_ros_diff_drive.so" name="differential_drive_controller_front">
      <left_joint>front_left_wheel_joint</left_joint>
      <right_joint>front_right_wheel_joint</right_joint>
      <wheel_separation>0.78796</wheel_separation>
      <wheel_diameter>0.23472</wheel_diameter>
      <!-- Output -->
      <odometry_frame>odom</odometry_frame>
      <robot_base_frame>base_link</robot_base_frame>
      <publish_odom>true</publish_odom>
      <publish_odom_tf>true</publish_odom_tf>
      <publish_wheel_tf>true</publish_wheel_tf>
    </plugin>
  </gazebo>
  <gazebo>
    <plugin filename="libgazebo_ros_diff_drive.so" name="differential_drive_controller_back">
      <left_joint>back_left_wheel_joint</left_joint>
      <right_joint>back_right_wheel_joint</right_joint>
      <wheel_separation>0.78796</wheel_separation>
      <wheel_diameter>0.23472</wheel_diameter>
      <!-- Output -->
      <odometry_frame>odom</odometry_frame>
      <robot_base_frame>base_link</robot_base_frame>
      <publish_odom>false</publish_odom>
      <publish_odom_tf>true</publish_odom_tf>
      <publish_wheel_tf>true</publish_wheel_tf>
    </plugin>
  </gazebo>
  <material name="red_laser">
    <color rgba="1 0 0 1"/>
  </material>
  <joint name="laser_joint" type="fixed">
    <parent link="chassis"/>
    <child link="laser_frame"/>
    <origin rpy="0 0 3.141592653589793" xyz="0.1 0 0.175"/>
  </joint>
  <link name="laser_frame">
    <visual>
      <geometry>
        <cylinder length="0.04" radius="0.05"/>
      </geometry>
      <material name="red_laser"/>
    </visual>
    <collision>
      <geometry>
        <cylinder length="0.04" radius="0.05"/>
      </geometry>
    </collision>
  </link>
  <gazebo reference="laser_frame">
    <material>Gazebo/Red</material>
    <sensor name="laser" type="ray">
      <pose> 0 0 0 0 0 0 </pose>
      <visualize>true</visualize>
      <update_rate>10</update_rate>
      <ray>
        <scan>
          <horizontal>
            <samples>360</samples>
            <min_angle>-3.14</min_angle>
            <max_angle>3.14</max_angle>
          </horizontal>
        </scan>
        <range>
          <min>0.15</min>
          <max>6</max>
        </range>
      </ray>
      <plugin filename="libgazebo_ros_ray_sensor.so" name="laser_controller">
        <ros>
          <argument>~/out:=scan</argument>
        </ros>
        <output_type>sensor_msgs/LaserScan</output_type>
        <frame_name>laser_frame</frame_name>
      </plugin>
    </sensor>
  </gazebo>
  <material name="red_camera">
    <color rgba="1 0 0 1"/>
  </material>
  <joint name="camera_joint" type="fixed">
    <parent link="chassis"/>
    <child link="camera_link"/>
    <origin rpy="0 0 0" xyz="0.205 0 0.08"/>
  </joint>
  <link name="camera_link">
    <visual>
      <geometry>
        <box size="0.010 0.03 0.03"/>
      </geometry>
      <material name="red_camera"/>
    </visual>
  </link>
  <joint name="camera_optical_joint" type="fixed">
    <parent link="camera_link"/>
    <child link="camera_link_optical"/>
    <origin rpy="-1.5707963267948966 0 -1.5707963267948966" xyz="0 0 0"/>
  </joint>
  <link name="camera_link_optical"/>
  <gazebo reference="camera_link">
    <material>Gazebo/Red</material>
    <sensor name="camera" type="camera">
      <pose> 0 0 0 0 0 0 </pose>
      <visualize>true</visualize>
      <update_rate>10</update_rate>
      <camera>
        <horizontal_fov>1.089</horizontal_fov>
        <image>
          <format>R8G8B8</format>
          <width>640</width>
          <height>480</height>
        </image>
        <clip>
          <near>0.05</near>
          <far>8.0</far>
        </clip>
      </camera>
      <plugin filename="libgazebo_ros_camera.so" name="camera_controller">
        <frame_name>camera_link_optical</frame_name>
      </plugin>
    </sensor>
  </gazebo>
</robot>
